Workbook

Sheet DispUEBD_AllRigs
A1: RigName | B1: RigSerialNumber | C1: Status | D1: DelayData | E1: Time | F1: EndTime | G1: ShiftName | H1: WorkDayStarted | I1: HourStarted_v12Hours | J1: HourStarted_v24Hours | K1: DrillPlan | L1: Operator | M1: STB | N1: AutoFunction | O1: Duration | P1: CodeName | Q1: ShortCode | R1: OnlyCodeNumber | S1: OnlyCodeName | T1: PlannedCodeName
A2: PF-07 | B2: 8999804000 | C2: Parked | E2: 46033.875 | F2: 46033.883 | G2: Turno A | H2: 2026-01-11 | I2: 9 | J2: 21 | K2: MAF11-W-3155-22 | L2: Sergio_Bravo_M. | O2: 663 | P2: 315_No_requerido | Q2: Reserva | R2: 315 | S2: No_requerido | T2: No Asignado
A3: PF-22 | B3: 8999801450 | C3: DelayCode | D3: 419_Mant_No_Program | E3: 46033.875 | F3: 46033.917 | G3: Turno A | H3: 2026-01-11 | I3: 9 | J3: 21 | K3: No Data | L3: None | M3: STB State Local Manual | N3: Manual | O3: 3600 | P3: 419_Mant_No_Program | Q3: Mantencion | R3: 419 | S3: Mant_No_Program | T3: No Programada
A4: PF-23 | B4: 8999801530 | C4: DelayCode | D4: 246_Cambio_Turno | E4: 46033.875 | F4: 46033.875 | G4: Turno A | H4: 2026-01-11 | I4: 9 | J4: 21 | K4: MAF09-SE-2825-01 | L4: Claudio_Maldonado_T | M4: STB State Local Manual | N4: Manual | O4: 26 | P4: 246_Cambio_Turno | Q4: Demora | R4: 246 | S4: Cambio_Turno | T4: Programada
A5: PF-21 | B5: 8999801320 | C5: DelayCode | D5: 282_Inter_Otros_Equ | E5: 46033.875 | F5: 46033.88 | G5: Turno A | H5: 2026-01-11 | I5: 9 | J5: 21 | K5: MAF09-SE-2840-15 | L5: None | M5: STB State Local Manual | N5: No Data | O5: 398 | P5: 282_Inter_Otros_Equ | Q5: Demora | R5: 282 | S5: Inter_Otros_Equ | T5: No Programada
A6: PF-26 | B6: 8999850070 | C6: DelayCode | D6: 246_Cambio_Turno | E6: 46033.875 | F6: 46033.88 | G6: Turno A | H6: 2026-01-11 | I6: 9 | J6: 21 | K6: MAF09-SE-2840-13 | L6: Luis_Oyarzun_V. | N6: Manual | O6: 435 | P6: 246_Cambio_Turno | Q6: Demora | R6: 246 | S6: Cambio_Turno | T6: Programada
A7: PF-24 | B7: 8999801700 | C7: DelayCode | D7: 246_Cambio_Turno | E7: 46033.875 | F7: 46033.875 | G7: Turno A | H7: 2026-01-11 | I7: 9 | J7: 21 | K7: No Data | L7: Cristian_Aguilera_B | M7: STB State Remote Switched | N7: Manual | O7: 24 | P7: 246_Cambio_Turno | Q7: Demora | R7: 246 | S7: Cambio_Turno | T7: Programada
A8: PF-25 | B8: 8999801690 | C8: DelayCode | D8: 223_Sin_Senal_GPS | E8: 46033.875 | F8: 46033.876 | G8: Turno A | H8: 2026-01-11 | I8: 9 | J8: 21 | L8: Iselda_Bugueno | M8: STB State Remote Allocated | N8: Manual | O8: 111 | P8: 223_Sin_Senal_GPS | Q8: Demora | R8: 223 | S8: Sin_Senal_GPS | T8: No Programada
A9: PF-24 | B9: 8999801700 | C9: DelayCode | D9: 246_Cambio_Turno | E9: 46033.875 | F9: 46033.88 | G9: Turno A | H9: 2026-01-11 | I9: 9 | J9: 21 | K9: No Data | L9: Cristian_Aguilera_B | M9: STB State E-Stop | N9: Manual | O9: 407 | P9: 246_Cambio_Turno | Q9: Demora | R9: 246 | S9: Cambio_Turno | T9: Programada
A10: PF-23 | B10: 8999801530 | C10: DelayCode | D10: 246_Cambio_Turno | E10: 46033.875 | F10: 46033.878 | G10: Turno A | H10: 2026-01-11 | I10: 9 | J10: 21 | K10: MAF09-SE-2825-01 | L10: Claudio_Maldonado_T | M10: STB State E-Stop | N10: Manual | O10: 211 | P10: 246_Cambio_Turno | Q10: Demora | R10: 246 | S10: Cambio_Turno | T10: Programada
A11: PF-25 | B11: 8999801690 | C11: DelayCode | D11: 223_Sin_Senal_GPS | E11: 46033.876 | F11: 46033.884 | G11: Turno A | H11: 2026-01-11 | I11: 9 | J11: 21 | L11: Alex_Pereira_P. | M11: STB State Remote Allocated | N11: Manual | O11: 633 | P11: 223_Sin_Senal_GPS | Q11: Demora | R11: 223 | S11: Sin_Senal_GPS | T11: No Programada
A12: PF-23 | B12: 8999801530 | C12: DelayCode | D12: 246_Cambio_Turno | E12: 46033.878 | F12: 46033.878 | G12: Turno A | H12: 2026-01-11 | I12: 9 | J12: 21 | K12: MAF09-SE-2825-01 | L12: Claudio_Maldonado_T | M12: STB State Local Manual | N12: Manual | O12: 26 | P12: 246_Cambio_Turno | Q12: Demora | R12: 246 | S12: Cambio_Turno | T12: Programada
A13: PF-23 | B13: 8999801530 | C13: DelayCode | D13: 246_Cambio_Turno | E13: 46033.878 | F13: 46033.878 | G13: Turno A | H13: 2026-01-11 | I13: 9 | J13: 21 | K13: MAF09-SE-2825-01 | L13: Claudio_Maldonado_T | M13: STB State Local Manual | N13: Manual | O13: 11 | P13: 246_Cambio_Turno | Q13: Demora | R13: 246 | S13: Cambio_Turno | T13: Programada
A14: PF-23 | B14: 8999801530 | C14: DelayCode | D14: 246_Cambio_Turno | E14: 46033.878 | F14: 46033.878 | G14: Turno A | H14: 2026-01-11 | I14: 9 | J14: 21 | K14: MAF09-SE-2825-01 | L14: Claudio_Maldonado_T | M14: STB State Local Manual | N14: Manual | O14: 2 | P14: 246_Cambio_Turno | Q14: Demora | R14: 246 | S14: Cambio_Turno | T14: Programada
A15: PF-23 | B15: 8999801530 | C15: Drilling | E15: 46033.878 | F15: 46033.879 | G15: Turno A | H15: 2026-01-11 | I15: 9 | J15: 21 | K15: MAF09-SE-2825-01 | L15: Claudio_Maldonado_T | M15: STB State Local Manual | N15: Manual | O15: 29 | P15: 106_Efectivo_Perforando | Q15: Efectivo | R15: 106 | S15: Efectivo_Perforando | T15: No Asignado
A16: PF-23 | B16: 8999801530 | C16: Drilling | E16: 46033.879 | F16: 46033.892 | G16: Turno A | H16: 2026-01-11 | I16: 9 | J16: 21 | K16: MAF09-SE-2825-01 | L16: Mariole_Rivero | M16: STB State Local Manual | N16: Manual | O16: 1206 | P16: 106_Efectivo_Perforando | Q16: Efectivo | R16: 106 | S16: Efectivo_Perforando | T16: No Asignado
A17: PF-21 | B17: 8999801320 | C17: DelayCode | D17: 282_Inter_Otros_Equ | E17: 46033.88 | F17: 46033.88 | G17: Turno A | H17: 2026-01-11 | I17: 9 | J17: 21 | K17: MAF09-SE-2840-15 | L17: None | M17: STB State Local Manual | N17: No Data | O17: 1 | P17: 282_Inter_Otros_Equ | Q17: Demora | R17: 282 | S17: Inter_Otros_Equ | T17: No Programada
A18: PF-21 | B18: 8999801320 | C18: DelayCode | D18: 282_Inter_Otros_Equ | E18: 46033.88 | F18: 46033.88 | G18: Turno A | H18: 2026-01-11 | I18: 9 | J18: 21 | K18: MAF09-SE-2840-15 | L18: None | M18: STB State E-Stop | N18: No Data | O18: 3 | P18: 282_Inter_Otros_Equ | Q18: Demora | R18: 282 | S18: Inter_Otros_Equ | T18: No Programada
A19: PF-21 | B19: 8999801320 | C19: DelayCode | D19: 282_Inter_Otros_Equ | E19: 46033.88 | F19: 46033.88 | G19: Turno A | H19: 2026-01-11 | I19: 9 | J19: 21 | K19: MAF09-SE-2840-15 | L19: None | M19: STB State Local Manual | N19: No Data | O19: 50 | P19: 282_Inter_Otros_Equ | Q19: Demora | R19: 282 | S19: Inter_Otros_Equ | T19: No Programada
A20: PF-24 | B20: 8999801700 | C20: DelayCode | D20: 246_Cambio_Turno | E20: 46033.88 | F20: 46033.882 | G20: Turno A | H20: 2026-01-11 | I20: 9 | J20: 21 | K20: No Data | L20: Cristian_Aguilera_B | M20: STB State Local Manual | N20: Manual | O20: 167 | P20: 246_Cambio_Turno | Q20: Demora | R20: 246 | S20: Cambio_Turno | T20: Programada
A21: PF-26 | B21: 8999850070 | C21: DelayCode | D21: 246_Cambio_Turno | E21: 46033.88 | F21: 46033.883 | G21: Turno A | H21: 2026-01-11 | I21: 9 | J21: 21 | K21: MAF09-SE-2840-13 | L21: Luis_Oyarzun_V. | N21: Manual | O21: 259 | P21: 246_Cambio_Turno | Q21: Demora | R21: 246 | S21: Cambio_Turno | T21: Programada
A22: PF-21 | B22: 8999801320 | C22: DelayCode | D22: 282_Inter_Otros_Equ | E22: 46033.88 | F22: 46033.881 | G22: Turno A | H22: 2026-01-11 | I22: 9 | J22: 21 | K22: MAF09-SE-2840-15 | L22: Emilio_Ferreira_V. | M22: STB State Local Manual | N22: No Data | O22: 24 | P22: 282_Inter_Otros_Equ | Q22: Demora | R22: 282 | S22: Inter_Otros_Equ | T22: No Programada
A23: PF-21 | B23: 8999801320 | C23: DelayCode | D23: 282_Inter_Otros_Equ | E23: 46033.881 | F23: 46033.881 | G23: Turno A | H23: 2026-01-11 | I23: 9 | J23: 21 | K23: MAF09-SE-2840-15 | L23: Emilio_Ferreira_V. | M23: STB State Local Manual | N23: No Data | O23: 9 | P23: 282_Inter_Otros_Equ | Q23: Demora | R23: 282 | S23: Inter_Otros_Equ | T23: No Programada
A24: PF-21 | B24: 8999801320 | C24: DelayCode | D24: 282_Inter_Otros_Equ | E24: 46033.881 | F24: 46033.886 | G24: Turno A | H24: 2026-01-11 | I24: 9 | J24: 21 | K24: MAF09-SE-2840-15 | L24: Emilio_Ferreira_V. | M24: STB State Local Manual | N24: No Data | O24: 442 | P24: 282_Inter_Otros_Equ | Q24: Demora | R24: 282 | S24: Inter_Otros_Equ | T24: No Programada
A25: PF-24 | B25: 8999801700 | C25: DelayCode | D25: 246_Cambio_Turno | E25: 46033.882 | F25: 46033.882 | G25: Turno A | H25: 2026-01-11 | I25: 9 | J25: 21 | K25: No Data | L25: Cristian_Aguilera_B | M25: STB State Local Manual | N25: Manual | O25: 27 | P25: 246_Cambio_Turno | Q25: Demora | R25: 246 | S25: Cambio_Turno | T25: Programada
A26: PF-24 | B26: 8999801700 | C26: DelayCode | D26: 246_Cambio_Turno | E26: 46033.882 | F26: 46033.885 | G26: Turno A | H26: 2026-01-11 | I26: 9 | J26: 21 | K26: No Data | L26: Cristian_Aguilera_B | M26: STB State Local Manual | N26: Manual | O26: 216 | P26: 246_Cambio_Turno | Q26: Demora | R26: 246 | S26: Cambio_Turno | T26: Programada
A27: PF-07 | B27: 8999804000 | C27: Positioning/Setup | E27: 46033.883 | F27: 46033.883 | G27: Turno A | H27: 2026-01-11 | I27: 9 | J27: 21 | K27: MAF11-W-3155-22 | L27: Sergio_Bravo_M. | O27: 59 | P27: 203_Demora_Posicion | Q27: Demora | R27: 203 | S27: Demora_Posicion | T27: No Programada
A28: PF-26 | B28: 8999850070 | C28: DelayCode | D28: 246_Cambio_Turno | E28: 46033.883 | F28: 46033.883 | G28: Turno A | H28: 2026-01-11 | I28: 9 | J28: 21 | K28: MAF09-SE-2840-13 | L28: Luis_Oyarzun_V. | N28: Manual | O28: 35 | P28: 246_Cambio_Turno | Q28: Demora | R28: 246 | S28: Cambio_Turno | T28: Programada
A29: PF-07 | B29: 8999804000 | C29: Positioning/Setup | E29: 46033.883 | F29: 46033.885 | G29: Turno A | H29: 2026-01-11 | I29: 9 | J29: 21 | K29: MAF11-W-3155-22 | L29: Misael_Tirado_P. | O29: 153 | P29: 203_Demora_Posicion | Q29: Demora | R29: 203 | S29: Demora_Posicion | T29: No Programada
A30: PF-26 | B30: 8999850070 | C30: DelayCode | D30: 246_Cambio_Turno | E30: 46033.883 | F30: 46033.884 | G30: Turno A | H30: 2026-01-11 | I30: 9 | J30: 21 | K30: MAF09-SE-2840-13 | L30: Luis_Oyarzun_V. | N30: Manual | O30: 8 | P30: 246_Cambio_Turno | Q30: Demora | R30: 246 | S30: Cambio_Turno | T30: Programada
A31: PF-26 | B31: 8999850070 | C31: Drilling | E31: 46033.884 | F31: 46033.884 | G31: Turno A | H31: 2026-01-11 | I31: 9 | J31: 21 | K31: MAF09-SE-2840-13 | L31: Luis_Oyarzun_V. | N31: Manual | O31: 6 | P31: 106_Efectivo_Perforando | Q31: Efectivo | R31: 106 | S31: Efectivo_Perforando | T31: No Asignado
A32: PF-26 | B32: 8999850070 | C32: Drilling | E32: 46033.884 | F32: 46033.905 | G32: Turno A | H32: 2026-01-11 | I32: 9 | J32: 21 | K32: MAF09-SE-2840-13 | L32: Lino_Alamos_R. | N32: Manual | O32: 1883 | P32: 106_Efectivo_Perforando | Q32: Efectivo | R32: 106 | S32: Efectivo_Perforando | T32: No Asignado
A33: PF-25 | B33: 8999801690 | C33: DelayCode | D33: 223_Sin_Senal_GPS | E33: 46033.884 | F33: 46033.884 | G33: Turno A | H33: 2026-01-11 | I33: 9 | J33: 21 | L33: Alex_Pereira_P. | M33: STB State Remote Allocated | N33: Manual | O33: 11 | P33: 223_Sin_Senal_GPS | Q33: Demora | R33: 223 | S33: Sin_Senal_GPS | T33: No Programada
A34: PF-25 | B34: 8999801690 | C34: DelayCode | D34: 223_Sin_Senal_GPS | E34: 46033.884 | F34: 46033.887 | G34: Turno A | H34: 2026-01-11 | I34: 9 | J34: 21 | L34: Alex_Pereira_P. | M34: STB State Remote Allocated | N34: Manual | O34: 259 | P34: 223_Sin_Senal_GPS | Q34: Demora | R34: 223 | S34: Sin_Senal_GPS | T34: No Programada
A35: PF-24 | B35: 8999801700 | C35: Drill Mode | E35: 46033.885 | F35: 46033.885 | G35: Turno A | H35: 2026-01-11 | I35: 9 | J35: 21 | K35: No Data | L35: Cristian_Aguilera_B | M35: STB State Local Manual | N35: Manual | O35: 17 | P35: 106_Efectivo_Perforando | Q35: Efectivo | R35: 106 | S35: Efectivo_Perforando | T35: No Asignado
A36: PF-24 | B36: 8999801700 | C36: Drill Mode | E36: 46033.885 | F36: 46033.892 | G36: Turno A | H36: 2026-01-11 | I36: 9 | J36: 21 | K36: No Data | L36: Iselda_Bugueno | M36: STB State Local Manual | N36: Manual | O36: 571 | P36: 106_Efectivo_Perforando | Q36: Efectivo | R36: 106 | S36: Efectivo_Perforando | T36: No Asignado
A37: PF-07 | B37: 8999804000 | C37: Drill Mode | E37: 46033.885 | F37: 46033.889 | G37: Turno A | H37: 2026-01-11 | I37: 9 | J37: 21 | K37: MAF11-W-3155-22 | L37: Misael_Tirado_P. | O37: 364 | P37: 106_Efectivo_Perforando | Q37: Efectivo | R37: 106 | S37: Efectivo_Perforando | T37: No Asignado
A38: PF-21 | B38: 8999801320 | C38: DelayCode | D38: 282_Inter_Otros_Equ | E38: 46033.886 | F38: 46033.887 | G38: Turno A | H38: 2026-01-11 | I38: 9 | J38: 21 | K38: MAF09-SE-2840-15 | L38: Emilio_Ferreira_V. | M38: STB State Local Manual | N38: No Data | O38: 86 | P38: 282_Inter_Otros_Equ | Q38: Demora | R38: 282 | S38: Inter_Otros_Equ | T38: No Programada
A39: PF-21 | B39: 8999801320 | C39: DelayCode | D39: 282_Inter_Otros_Equ | E39: 46033.887 | F39: 46033.887 | G39: Turno A | H39: 2026-01-11 | I39: 9 | J39: 21 | K39: MAF09-SE-2840-15 | L39: Emilio_Ferreira_V. | M39: STB State Local Manual | N39: No Data | O39: 12 | P39: 282_Inter_Otros_Equ | Q39: Demora | R39: 282 | S39: Inter_Otros_Equ | T39: No Programada
A40: PF-25 | B40: 8999801690 | C40: Drill Mode | E40: 46033.887 | F40: 46033.917 | G40: Turno A | H40: 2026-01-11 | I40: 9 | J40: 21 | L40: Alex_Pereira_P. | M40: STB State Remote Allocated | N40: Manual | O40: 2586 | P40: 106_Efectivo_Perforando | Q40: Efectivo | R40: 106 | S40: Efectivo_Perforando | T40: No Asignado
...

Sheet Resumen
A1: Reporte DispUEBD_AllRigs
B2: PF-07 | C2: PF-21 | D2: PF-22 | E2: PF-23 | F2: PF-24 | G2: PF-25 | H2: PF-26
A3: fecha inicio | B3: {=MIN(IF('DispUEBD_AllRigs'!A2:A980=B2,'DispUEBD_AllRigs'!E2:E980))} -> 0 | C3: {=MIN(IF('DispUEBD_AllRigs'!A2:A980=C2,'DispUEBD_AllRigs'!E2:E980))} -> 0 | D3: {=MIN(IF('DispUEBD_AllRigs'!A2:A980=D2,'DispUEBD_AllRigs'!E2:E980))} -> 0 | E3: {=MIN(IF('DispUEBD_AllRigs'!A2:A980=E2,'DispUEBD_AllRigs'!E2:E980))} -> 0 | F3: {=MIN(IF('DispUEBD_AllRigs'!A2:A980=F2,'DispUEBD_AllRigs'!E2:E980))} -> 0 | G3: {=MIN(IF('DispUEBD_AllRigs'!A2:A980=G2,'DispUEBD_AllRigs'!E2:E980))} -> 0 | H3: {=MIN(IF('DispUEBD_AllRigs'!A2:A980=H2,'DispUEBD_AllRigs'!E2:E980))} -> 0
A4: fecha fin | B4: {=MAX(IF('DispUEBD_AllRigs'!A2:A980=B2,'DispUEBD_AllRigs'!F2:F980))} -> 0 | C4: {=MAX(IF('DispUEBD_AllRigs'!A2:A980=C2,'DispUEBD_AllRigs'!F2:F980))} -> 0 | D4: {=MAX(IF('DispUEBD_AllRigs'!A2:A980=D2,'DispUEBD_AllRigs'!F2:F980))} -> 0 | E4: {=MAX(IF('DispUEBD_AllRigs'!A2:A980=E2,'DispUEBD_AllRigs'!F2:F980))} -> 0 | F4: {=MAX(IF('DispUEBD_AllRigs'!A2:A980=F2,'DispUEBD_AllRigs'!F2:F980))} -> 0 | G4: {=MAX(IF('DispUEBD_AllRigs'!A2:A980=G2,'DispUEBD_AllRigs'!F2:F980))} -> 0 | H4: {=MAX(IF('DispUEBD_AllRigs'!A2:A980=H2,'DispUEBD_AllRigs'!F2:F980))} -> 0
A5: Horas total | B5: =SUMIFS('DispUEBD_AllRigs'!O2:O980,'DispUEBD_AllRigs'!A2:A980,B2)/3600 -> 0 | C5: =SUMIFS('DispUEBD_AllRigs'!O2:O980,'DispUEBD_AllRigs'!A2:A980,C2)/3600 -> 0 | D5: =SUMIFS('DispUEBD_AllRigs'!O2:O980,'DispUEBD_AllRigs'!A2:A980,D2)/3600 -> 0 | E5: =SUMIFS('DispUEBD_AllRigs'!O2:O980,'DispUEBD_AllRigs'!A2:A980,E2)/3600 -> 0 | F5: =SUMIFS('DispUEBD_AllRigs'!O2:O980,'DispUEBD_AllRigs'!A2:A980,F2)/3600 -> 0 | G5: =SUMIFS('DispUEBD_AllRigs'!O2:O980,'DispUEBD_AllRigs'!A2:A980,G2)/3600 -> 0 | H5: =SUMIFS('DispUEBD_AllRigs'!O2:O980,'DispUEBD_AllRigs'!A2:A980,H2)/3600 -> 0
A7: Efectivo PF | B7: =SUMIFS('DispUEBD_AllRigs'!O2:O980,'DispUEBD_AllRigs'!P2:P980,"=106_Efectivo_Perforando",'DispUEBD_AllRigs'!A2:A980,B2)/3600 -> 0 | C7: =SUMIFS('DispUEBD_AllRigs'!O2:O980,'DispUEBD_AllRigs'!P2:P980,"=106_Efectivo_Perforando",'DispUEBD_AllRigs'!A2:A980,C2)/3600 -> 0 | D7: =SUMIFS('DispUEBD_AllRigs'!O2:O980,'DispUEBD_AllRigs'!P2:P980,"=106_Efectivo_Perforando",'DispUEBD_AllRigs'!A2:A980,D2)/3600 -> 0 | E7: =SUMIFS('DispUEBD_AllRigs'!O2:O980,'DispUEBD_AllRigs'!P2:P980,"=106_Efectivo_Perforando",'DispUEBD_AllRigs'!A2:A980,E2)/3600 -> 0 | F7: =SUMIFS('DispUEBD_AllRigs'!O2:O980,'DispUEBD_AllRigs'!P2:P980,"=106_Efectivo_Perforando",'DispUEBD_AllRigs'!A2:A980,F2)/3600 -> 0 | G7: =SUMIFS('DispUEBD_AllRigs'!O2:O980,'DispUEBD_AllRigs'!P2:P980,"=106_Efectivo_Perforando",'DispUEBD_AllRigs'!A2:A980,G2)/3600 -> 0 | H7: =SUMIFS('DispUEBD_AllRigs'!O2:O980,'DispUEBD_AllRigs'!P2:P980,"=106_Efectivo_Perforando",'DispUEBD_AllRigs'!A2:A980,H2)/3600 -> 0
A8: Efectivo Total | B8: =SUMIFS('DispUEBD_AllRigs'!O2:O980,'DispUEBD_AllRigs'!Q2:Q980,"=Efectivo",'DispUEBD_AllRigs'!A2:A980,B2)/3600 -> 0 | C8: =SUMIFS('DispUEBD_AllRigs'!O2:O980,'DispUEBD_AllRigs'!Q2:Q980,"=Efectivo",'DispUEBD_AllRigs'!A2:A980,C2)/3600 -> 0 | D8: =SUMIFS('DispUEBD_AllRigs'!O2:O980,'DispUEBD_AllRigs'!Q2:Q980,"=Efectivo",'DispUEBD_AllRigs'!A2:A980,D2)/3600 -> 0 | E8: =SUMIFS('DispUEBD_AllRigs'!O2:O980,'DispUEBD_AllRigs'!Q2:Q980,"=Efectivo",'DispUEBD_AllRigs'!A2:A980,E2)/3600 -> 0 | F8: =SUMIFS('DispUEBD_AllRigs'!O2:O980,'DispUEBD_AllRigs'!Q2:Q980,"=Efectivo",'DispUEBD_AllRigs'!A2:A980,F2)/3600 -> 0 | G8: =SUMIFS('DispUEBD_AllRigs'!O2:O980,'DispUEBD_AllRigs'!Q2:Q980,"=Efectivo",'DispUEBD_AllRigs'!A2:A980,G2)/3600 -> 0 | H8: =SUMIFS('DispUEBD_AllRigs'!O2:O980,'DispUEBD_AllRigs'!Q2:Q980,"=Efectivo",'DispUEBD_AllRigs'!A2:A980,H2)/3600 -> 0
A9: Mantención Progamada | B9: =SUMIFS('DispUEBD_AllRigs'!O2:O980,'DispUEBD_AllRigs'!Q2:Q980,"=Mantencion",'DispUEBD_AllRigs'!T2:T980,"=Programada",'DispUEBD_AllRigs'!A2:A980,B2)/3600 -> 0 | C9: =SUMIFS('DispUEBD_AllRigs'!O2:O980,'DispUEBD_AllRigs'!Q2:Q980,"=Mantencion",'DispUEBD_AllRigs'!T2:T980,"=Programada",'DispUEBD_AllRigs'!A2:A980,C2)/3600 -> 0 | D9: =SUMIFS('DispUEBD_AllRigs'!O2:O980,'DispUEBD_AllRigs'!Q2:Q980,"=Mantencion",'DispUEBD_AllRigs'!T2:T980,"=Programada",'DispUEBD_AllRigs'!A2:A980,D2)/3600 -> 0 | E9: =SUMIFS('DispUEBD_AllRigs'!O2:O980,'DispUEBD_AllRigs'!Q2:Q980,"=Mantencion",'DispUEBD_AllRigs'!T2:T980,"=Programada",'DispUEBD_AllRigs'!A2:A980,E2)/3600 -> 0 | F9: =SUMIFS('DispUEBD_AllRigs'!O2:O980,'DispUEBD_AllRigs'!Q2:Q980,"=Mantencion",'DispUEBD_AllRigs'!T2:T980,"=Programada",'DispUEBD_AllRigs'!A2:A980,F2)/3600 -> 0 | G9: =SUMIFS('DispUEBD_AllRigs'!O2:O980,'DispUEBD_AllRigs'!Q2:Q980,"=Mantencion",'DispUEBD_AllRigs'!T2:T980,"=Programada",'DispUEBD_AllRigs'!A2:A980,G2)/3600 -> 0 | H9: =SUMIFS('DispUEBD_AllRigs'!O2:O980,'DispUEBD_AllRigs'!Q2:Q980,"=Mantencion",'DispUEBD_AllRigs'!T2:T980,"=Programada",'DispUEBD_AllRigs'!A2:A980,H2)/3600 -> 0
A10: Mantención No Progamada | B10: =SUMIFS('DispUEBD_AllRigs'!O2:O980,'DispUEBD_AllRigs'!Q2:Q980,"=Mantencion",'DispUEBD_AllRigs'!T2:T980,"=No Programada",'DispUEBD_AllRigs'!A2:A980,B2)/3600 -> 0 | C10: =SUMIFS('DispUEBD_AllRigs'!O2:O980,'DispUEBD_AllRigs'!Q2:Q980,"=Mantencion",'DispUEBD_AllRigs'!T2:T980,"=No Programada",'DispUEBD_AllRigs'!A2:A980,C2)/3600 -> 0 | D10: =SUMIFS('DispUEBD_AllRigs'!O2:O980,'DispUEBD_AllRigs'!Q2:Q980,"=Mantencion",'DispUEBD_AllRigs'!T2:T980,"=No Programada",'DispUEBD_AllRigs'!A2:A980,D2)/3600 -> 0 | E10: =SUMIFS('DispUEBD_AllRigs'!O2:O980,'DispUEBD_AllRigs'!Q2:Q980,"=Mantencion",'DispUEBD_AllRigs'!T2:T980,"=No Programada",'DispUEBD_AllRigs'!A2:A980,E2)/3600 -> 0 | F10: =SUMIFS('DispUEBD_AllRigs'!O2:O980,'DispUEBD_AllRigs'!Q2:Q980,"=Mantencion",'DispUEBD_AllRigs'!T2:T980,"=No Programada",'DispUEBD_AllRigs'!A2:A980,F2)/3600 -> 0 | G10: =SUMIFS('DispUEBD_AllRigs'!O2:O980,'DispUEBD_AllRigs'!Q2:Q980,"=Mantencion",'DispUEBD_AllRigs'!T2:T980,"=No Programada",'DispUEBD_AllRigs'!A2:A980,G2)/3600 -> 0 | H10: =SUMIFS('DispUEBD_AllRigs'!O2:O980,'DispUEBD_AllRigs'!Q2:Q980,"=Mantencion",'DispUEBD_AllRigs'!T2:T980,"=No Programada",'DispUEBD_AllRigs'!A2:A980,H2)/3600 -> 0
A11: Reserva | B11: =SUMIFS('DispUEBD_AllRigs'!O2:O980,'DispUEBD_AllRigs'!Q2:Q980,"=Reserva",'DispUEBD_AllRigs'!A2:A980,B2)/3600 -> 0 | C11: =SUMIFS('DispUEBD_AllRigs'!O2:O980,'DispUEBD_AllRigs'!Q2:Q980,"=Reserva",'DispUEBD_AllRigs'!A2:A980,C2)/3600 -> 0 | D11: =SUMIFS('DispUEBD_AllRigs'!O2:O980,'DispUEBD_AllRigs'!Q2:Q980,"=Reserva",'DispUEBD_AllRigs'!A2:A980,D2)/3600 -> 0 | E11: =SUMIFS('DispUEBD_AllRigs'!O2:O980,'DispUEBD_AllRigs'!Q2:Q980,"=Reserva",'DispUEBD_AllRigs'!A2:A980,E2)/3600 -> 0 | F11: =SUMIFS('DispUEBD_AllRigs'!O2:O980,'DispUEBD_AllRigs'!Q2:Q980,"=Reserva",'DispUEBD_AllRigs'!A2:A980,F2)/3600 -> 0 | G11: =SUMIFS('DispUEBD_AllRigs'!O2:O980,'DispUEBD_AllRigs'!Q2:Q980,"=Reserva",'DispUEBD_AllRigs'!A2:A980,G2)/3600 -> 0 | H11: =SUMIFS('DispUEBD_AllRigs'!O2:O980,'DispUEBD_AllRigs'!Q2:Q980,"=Reserva",'DispUEBD_AllRigs'!A2:A980,H2)/3600 -> 0
A12: Demora Programada | B12: =SUMIFS('DispUEBD_AllRigs'!O2:O980,'DispUEBD_AllRigs'!Q2:Q980,"=Demora",'DispUEBD_AllRigs'!T2:T980,"=Programada",'DispUEBD_AllRigs'!A2:A980,B2)/3600 -> 0 | C12: =SUMIFS('DispUEBD_AllRigs'!O2:O980,'DispUEBD_AllRigs'!Q2:Q980,"=Demora",'DispUEBD_AllRigs'!T2:T980,"=Programada",'DispUEBD_AllRigs'!A2:A980,C2)/3600 -> 0 | D12: =SUMIFS('DispUEBD_AllRigs'!O2:O980,'DispUEBD_AllRigs'!Q2:Q980,"=Demora",'DispUEBD_AllRigs'!T2:T980,"=Programada",'DispUEBD_AllRigs'!A2:A980,D2)/3600 -> 0 | E12: =SUMIFS('DispUEBD_AllRigs'!O2:O980,'DispUEBD_AllRigs'!Q2:Q980,"=Demora",'DispUEBD_AllRigs'!T2:T980,"=Programada",'DispUEBD_AllRigs'!A2:A980,E2)/3600 -> 0 | F12: =SUMIFS('DispUEBD_AllRigs'!O2:O980,'DispUEBD_AllRigs'!Q2:Q980,"=Demora",'DispUEBD_AllRigs'!T2:T980,"=Programada",'DispUEBD_AllRigs'!A2:A980,F2)/3600 -> 0 | G12: =SUMIFS('DispUEBD_AllRigs'!O2:O980,'DispUEBD_AllRigs'!Q2:Q980,"=Demora",'DispUEBD_AllRigs'!T2:T980,"=Programada",'DispUEBD_AllRigs'!A2:A980,G2)/3600 -> 0 | H12: =SUMIFS('DispUEBD_AllRigs'!O2:O980,'DispUEBD_AllRigs'!Q2:Q980,"=Demora",'DispUEBD_AllRigs'!T2:T980,"=Programada",'DispUEBD_AllRigs'!A2:A980,H2)/3600 -> 0
A13: Demora No Programada | B13: =SUMIFS('DispUEBD_AllRigs'!O2:O980,'DispUEBD_AllRigs'!Q2:Q980,"=Demora",'DispUEBD_AllRigs'!T2:T980,"=No Programada",'DispUEBD_AllRigs'!A2:A980,B2)/3600 -> 0 | C13: =SUMIFS('DispUEBD_AllRigs'!O2:O980,'DispUEBD_AllRigs'!Q2:Q980,"=Demora",'DispUEBD_AllRigs'!T2:T980,"=No Programada",'DispUEBD_AllRigs'!A2:A980,C2)/3600 -> 0 | D13: =SUMIFS('DispUEBD_AllRigs'!O2:O980,'DispUEBD_AllRigs'!Q2:Q980,"=Demora",'DispUEBD_AllRigs'!T2:T980,"=No Programada",'DispUEBD_AllRigs'!A2:A980,D2)/3600 -> 0 | E13: =SUMIFS('DispUEBD_AllRigs'!O2:O980,'DispUEBD_AllRigs'!Q2:Q980,"=Demora",'DispUEBD_AllRigs'!T2:T980,"=No Programada",'DispUEBD_AllRigs'!A2:A980,E2)/3600 -> 0 | F13: =SUMIFS('DispUEBD_AllRigs'!O2:O980,'DispUEBD_AllRigs'!Q2:Q980,"=Demora",'DispUEBD_AllRigs'!T2:T980,"=No Programada",'DispUEBD_AllRigs'!A2:A980,F2)/3600 -> 0 | G13: =SUMIFS('DispUEBD_AllRigs'!O2:O980,'DispUEBD_AllRigs'!Q2:Q980,"=Demora",'DispUEBD_AllRigs'!T2:T980,"=No Programada",'DispUEBD_AllRigs'!A2:A980,G2)/3600 -> 0 | H13: =SUMIFS('DispUEBD_AllRigs'!O2:O980,'DispUEBD_AllRigs'!Q2:Q980,"=Demora",'DispUEBD_AllRigs'!T2:T980,"=No Programada",'DispUEBD_AllRigs'!A2:A980,H2)/3600 -> 0
A14: Sin patio | B14: =SUM(SUMIFS('DispUEBD_AllRigs'!O2:O980,'DispUEBD_AllRigs'!P2:P980,{"276_SN_Marca_Perfor","276_SN_Area_Perfor","315_No_requerido","RS No Requerido"},'DispUEBD_AllRigs'!A2:A980,B2))/3600 -> 0 | C14: =SUM(SUMIFS('DispUEBD_AllRigs'!O2:O980,'DispUEBD_AllRigs'!P2:P980,{"276_SN_Marca_Perfor","276_SN_Area_Perfor","315_No_requerido","RS No Requerido"},'DispUEBD_AllRigs'!A2:A980,C2))/3600 -> 0 | D14: =SUM(SUMIFS('DispUEBD_AllRigs'!O2:O980,'DispUEBD_AllRigs'!P2:P980,{"276_SN_Marca_Perfor","276_SN_Area_Perfor","315_No_requerido","RS No Requerido"},'DispUEBD_AllRigs'!A2:A980,D2))/3600 -> 0 | E14: =SUM(SUMIFS('DispUEBD_AllRigs'!O2:O980,'DispUEBD_AllRigs'!P2:P980,{"276_SN_Marca_Perfor","276_SN_Area_Perfor","315_No_requerido","RS No Requerido"},'DispUEBD_AllRigs'!A2:A980,E2))/3600 -> 0 | F14: =SUM(SUMIFS('DispUEBD_AllRigs'!O2:O980,'DispUEBD_AllRigs'!P2:P980,{"276_SN_Marca_Perfor","276_SN_Area_Perfor","315_No_requerido","RS No Requerido"},'DispUEBD_AllRigs'!A2:A980,F2))/3600 -> 0 | G14: =SUM(SUMIFS('DispUEBD_AllRigs'!O2:O980,'DispUEBD_AllRigs'!P2:P980,{"276_SN_Marca_Perfor","276_SN_Area_Perfor","315_No_requerido","RS No Requerido"},'DispUEBD_AllRigs'!A2:A980,G2))/3600 -> 0 | H14: =SUM(SUMIFS('DispUEBD_AllRigs'!O2:O980,'DispUEBD_AllRigs'!P2:P980,{"276_SN_Marca_Perfor","276_SN_Area_Perfor","315_No_requerido","RS No Requerido"},'DispUEBD_AllRigs'!A2:A980,H2))/3600 -> 0
A16: DISP (%) | B16: =(B8+B11+B13+B12)/(B8+B11+B9+B10+B12+B13) -> 0 | C16: =(C8+C11+C13+C12)/(C8+C11+C9+C10+C12+C13) -> 0 | D16: =(D8+D11+D13+D12)/(D8+D11+D9+D10+D12+D13) -> 0 | E16: =(E8+E11+E13+E12)/(E8+E11+E9+E10+E12+E13) -> 0 | F16: =(F8+F11+F13+F12)/(F8+F11+F9+F10+F12+F13) -> 0 | G16: =(G8+G11+G13+G12)/(G8+G11+G9+G10+G12+G13) -> 0 | H16: =(H8+H11+H13+H12)/(H8+H11+H9+H10+H12+H13) -> 0
A17: DISP Autonomia (%) | B17: =(B5-B9-B10-SUMIF('DispUEBD_AllRigs'!P2:P980,"=210_Falla_Autonomia",'DispUEBD_AllRigs'!O2:O980)/3600)/(B5-B9-B10) -> 0 | C17: =(C5-C9-C10-SUMIF('DispUEBD_AllRigs'!P2:P980,"=210_Falla_Autonomia",'DispUEBD_AllRigs'!O2:O980)/3600)/(C5-C9-C10) -> 0 | D17: =(D5-D9-D10-SUMIF('DispUEBD_AllRigs'!P2:P980,"=210_Falla_Autonomia",'DispUEBD_AllRigs'!O2:O980)/3600)/(D5-D9-D10) -> 0 | E17: =(E5-E9-E10-SUMIF('DispUEBD_AllRigs'!P2:P980,"=210_Falla_Autonomia",'DispUEBD_AllRigs'!O2:O980)/3600)/(E5-E9-E10) -> 0 | F17: =(F5-F9-F10-SUMIF('DispUEBD_AllRigs'!P2:P980,"=210_Falla_Autonomia",'DispUEBD_AllRigs'!O2:O980)/3600)/(F5-F9-F10) -> 0 | G17: =(G5-G9-G10-SUMIF('DispUEBD_AllRigs'!P2:P980,"=210_Falla_Autonomia",'DispUEBD_AllRigs'!O2:O980)/3600)/(G5-G9-G10) -> 0 | H17: =(H5-H9-H10-SUMIF('DispUEBD_AllRigs'!P2:P980,"=210_Falla_Autonomia",'DispUEBD_AllRigs'!O2:O980)/3600)/(H5-H9-H10) -> 0
A18: UEBD (%) | B18: =B8/(B8+B11+B13+B12) -> 0 | C18: =C8/(C8+C11+C13+C12) -> 0 | D18: =D8/(D8+D11+D13+D12) -> 0 | E18: =E8/(E8+E11+E13+E12) -> 0 | F18: =F8/(F8+F11+F13+F12) -> 0 | G18: =G8/(G8+G11+G13+G12) -> 0 | H18: =H8/(H8+H11+H13+H12) -> 0
A19: UEBD ajustada (%) | B19: =B8/(B8+B11+B13+B12-B14) -> 0 | C19: =C8/(C8+C11+C13+C12-C14) -> 0 | D19: =D8/(D8+D11+D13+D12-D14) -> 0 | E19: =E8/(E8+E11+E13+E12-E14) -> 0 | F19: =F8/(F8+F11+F13+F12-F14) -> 0 | G19: =G8/(G8+G11+G13+G12-G14) -> 0 | H19: =H8/(H8+H11+H13+H12-H14) -> 0
A20: Imprevisto (Horas) | B20: 0 | C20: 0 | D20: 4.6219444 | E20: 0.78305556 | F20: 0 | G20: 0 | H20: 0.29305556
A21: N° Imprevistos | B21: 0 | C21: 0 | D21: 1 | E21: 1 | F21: 0 | G21: 0 | H21: 1
A22: MTBF (Horas) | B22: =IF(B21,(B5-B9-B10-B11)/B21,NA()) -> 0 | C22: =IF(C21,(C5-C9-C10-C11)/C21,NA()) -> 0 | D22: =IF(D21,(D5-D9-D10-D11)/D21,NA()) -> 0 | E22: =IF(E21,(E5-E9-E10-E11)/E21,NA()) -> 0 | F22: =IF(F21,(F5-F9-F10-F11)/F21,NA()) -> 0 | G22: =IF(G21,(G5-G9-G10-G11)/G21,NA()) -> 0 | H22: =IF(H21,(H5-H9-H10-H11)/H21,NA()) -> 0
A23: MTTR (Horas) | B23: =IF(B21,B20/B21,NA()) -> 0 | C23: =IF(C21,C20/C21,NA()) -> 0 | D23: =IF(D21,D20/D21,NA()) -> 0 | E23: =IF(E21,E20/E21,NA()) -> 0 | F23: =IF(F21,F20/F21,NA()) -> 0 | G23: =IF(G21,G20/G21,NA()) -> 0 | H23: =IF(H21,H20/H21,NA()) -> 0
A25: Pozos | B25: 29 | C25: 15 | D25: 5 | E25: 13 | F25: 0 | G25: 0 | H25: 13
A26: Metros | B26: 509.65299 | C26: 255.66831 | D26: 88.328613 | E26: 217.05318 | F26: 0 | G26: 0 | H26: 220.79538
A28: Rendimiento ef (m/h) | B28: =IF(B7,B26/B7,NA()) -> 0 | C28: =IF(C7,C26/C7,NA()) -> 0 | D28: =IF(D7,D26/D7,NA()) -> 0 | E28: =IF(E7,E26/E7,NA()) -> 0 | F28: =IF(F7,F26/F7,NA()) -> 0 | G28: =IF(G7,G26/G7,NA()) -> 0 | H28: =IF(H7,H26/H7,NA()) -> 0
A29: Rendimiento ASARCO (m/h) | B29: =IF(B8,B26/B8,NA()) -> 0 | C29: =IF(C8,C26/C8,NA()) -> 0 | D29: =IF(D8,D26/D8,NA()) -> 0 | E29: =IF(E8,E26/E8,NA()) -> 0 | F29: =IF(F8,F26/F8,NA()) -> 0 | G29: =IF(G8,G26/G8,NA()) -> 0 | H29: =IF(H8,H26/H8,NA()) -> 0
A31: Promedio penetración (m/h) | B31: 76.531034 | C31: 34.484 | D31: 26.802 | E31: 30.290769 | F31: 0 | G31: 0 | H31: 33.856154
A32: Promedio Penetración < 3 mts (m/h) | B32: 107.56759 | C32: 44.776 | D32: 26.928 | E32: 40.013077 | F32: 0 | G32: 0 | H32: 51.833077
A33: Promedio Penetración > 3 mts (m/h) | B33: 76.74 | C33: 34.476 | D33: 26.808 | E33: 30.230769 | F33: 0 | G33: 0 | H33: 32.090769
A34: Promedio Dureza (MPa) | B34: 86.448198 | C34: 124.80813 | D34: 0 | E34: 116.424 | F34: 0 | G34: 0 | H34: 140.70597
A35: Promedio Dureza < 3 mts (MPa) | B35: 65.441088 | C35: 77.156399 | D35: 0 | E35: 68.7059 | F35: 0 | G35: 0 | H35: 61.116188
A36: Promedio Dureza > 3 mts (MPa) | B36: 90.346742 | C36: 134.0821 | D36: 0 | E36: 125.79567 | F36: 0 | G36: 0 | H36: 157.08429
A37: Promedio PullDown (klbf) | B37: 88.706649 | C37: 86.288787 | D37: 94.919561 | E37: 99.454615 | F37: 0 | G37: 0 | H37: 89.308298
A38: Promedio PullDown < 3 mts (klbf) | B38: 63.692739 | C38: 36.136278 | D38: 44.240133 | E38: 44.131512 | F38: 0 | G38: 0 | H38: 41.473218
A39: Promedio PullDown > 3 mts (klbf) | B39: 93.340561 | C39: 96.059919 | D39: 104.19484 | E39: 110.24421 | F39: 0 | G39: 0 | H39: 99.260054
A40: Promedio RPM (RPM) | B40: 95.119406 | C40: 88.64486 | D40: 96.883506 | E40: 96.314607 | F40: 0 | G40: 0 | H40: 100.28441
A41: Promedio RPM < 3 mts (RPM) | B41: 89.793552 | C41: 77.808459 | D41: 79.837044 | E41: 85.639088 | F41: 0 | G41: 0 | H41: 83.651506
A42: Promedio RPM > 3 mts (RPM) | B42: 96.10222 | C42: 90.752581 | D42: 99.980737 | E42: 98.405009 | F42: 0 | G42: 0 | H42: 103.73304
... A44: Pozos omitidos por dureza | B44: 0 | C44: 0 | D44: 5 | E44: 0 | F44: 0 | G44: 0 | H44: 0
